<?xml version="1.0" encoding="UTF-8"?>
<!-- Generated by org.testng.reporters.JUnitXMLReporter -->
<testsuite hostname="SAPTEST_A00" name="Navegacion_Header1" tests="8" failures="2" timestamp="17 Aug 2017 15:18:55 GMT" time="19.174" errors="0">
  <testcase name="NuevosAlumnos" time="0.891" classname="Salle.TestClasses.prueba"/>
  <testcase name="NuevosAlumnos" time="0.684" classname="Salle.TestClasses.SalleHeader"/>
  <testcase name="Alumnos" time="1.572" classname="Salle.TestClasses.prueba"/>
  <testcase name="Alumnos" time="1.645" classname="Salle.TestClasses.SalleHeader"/>
  <testcase name="Alumni" time="1.256" classname="Salle.TestClasses.prueba"/>
  <testcase name="Empresas" time="1.627" classname="Salle.TestClasses.prueba">
    <failure type="java.lang.AssertionError" message="expected [2] but found [1]">
      <![CDATA[java.lang.AssertionError: expected [2] but found [1]
	at Salle.TestClasses.prueba.Empresas(prueba.java:81)
	at java.util.concurrent.ThreadPoolExecutor.runWorker(ThreadPoolExecutor.java:1149)
	at java.util.concurrent.ThreadPoolExecutor$Worker.run(ThreadPoolExecutor.java:624)
	at java.lang.Thread.run(Thread.java:748)
... Removed 15 stack frames]]>
    </failure>
  </testcase> <!-- Empresas -->
  <testcase name="Alumni" time="4.412" classname="Salle.TestClasses.SalleHeader"/>
  <testcase name="Empresas" time="0.536" classname="Salle.TestClasses.SalleHeader">
    <failure type="java.lang.AssertionError" message="expected [2] but found [1]">
      <![CDATA[java.lang.AssertionError: expected [2] but found [1]
	at Salle.TestClasses.SalleHeader.Empresas(SalleHeader.java:96)
	at java.util.concurrent.ThreadPoolExecutor.runWorker(ThreadPoolExecutor.java:1149)
	at java.util.concurrent.ThreadPoolExecutor$Worker.run(ThreadPoolExecutor.java:624)
	at java.lang.Thread.run(Thread.java:748)
... Removed 15 stack frames]]>
    </failure>
  </testcase> <!-- Empresas -->
</testsuite> <!-- Navegacion_Header1 -->
